<?xml version="1.0"?>
<robot xmlns:xacro="http://ros.org/wiki/xacro" name="my_robot">

  <!-- Parameters -->
  <xacro:property name="wheel_radius" value="0.05"/>
  <xacro:property name="wheel_width" value="0.02"/>
  <xacro:property name="base_length" value="0.3"/>
  <xacro:property name="base_width"  value="0.3"/>
  <xacro:property name="base_height" value="0.1"/>
  <xacro:property name="mass"        value="1.0"/>

  <!-- Base link -->
  <link name="base_link">
    <inertial>
      <mass value="${mass}"/>
      <origin xyz="0 0 0" rpy="0 0 0"/>
      <inertia
        ixx="0.01" ixy="0.0" ixz="0.0"
        iyy="0.01" iyz="0.0"
        izz="0.01"/>
    </inertial>
    <visual>
      <geometry>
        <box size="${base_length} ${base_width} ${base_height}"/>
      </geometry>
      <origin xyz="0 0 ${base_height/2}" rpy="0 0 0"/>
      <material name="blue"><color rgba="0 0 1 1"/></material>
    </visual>
    <collision>
      <geometry>
        <box size="${base_length} ${base_width} ${base_height}"/>
      </geometry>
      <origin xyz="0 0 ${base_height/2}" rpy="0 0 0"/>
    </collision>
  </link>

  <!-- Wheels -->
  <xacro:macro name="wheel" params="prefix x y">
    <link name="${prefix}_wheel_link">
      <visual>
        <geometry>
          <cylinder radius="${wheel_radius}" length="${wheel_width}"/>
        </geometry>
        <origin xyz="${x} ${y} ${wheel_radius}" rpy="1.5708 0 0"/>
        <material name="black"><color rgba="0 0 0 1"/></material>
      </visual>
      <collision>
        <geometry>
          <cylinder radius="${wheel_radius}" length="${wheel_width}"/>
        </geometry>
        <origin xyz="${x} ${y} ${wheel_radius}" rpy="1.5708 0 0"/>
      </collision>
    </link>
    <joint name="${prefix}_wheel_joint" type="continuous">
      <parent link="base_link"/>
      <child link="${prefix}_wheel_link"/>
      <origin xyz="${x} ${y} ${wheel_radius}" rpy="0 0 0"/>
      <axis xyz="0 1 0"/>
    </joint>
  </xacro:macro>

  <xacro:wheel prefix="left"  x="0" y="0.15"/>
  <xacro:wheel prefix="right" x="0" y="-0.15"/>

</robot>
